#VRML_SIM R2023b utf8

EXTERNPROTO "https://raw.githubusercontent.com/cyberbotics/webots/R2023b/projects/objects/backgrounds/protos/TexturedBackground.proto"
EXTERNPROTO "https://raw.githubusercontent.com/cyberbotics/webots/R2023b/projects/objects/backgrounds/protos/TexturedBackgroundLight.proto"
EXTERNPROTO "https://raw.githubusercontent.com/cyberbotics/webots/R2023b/projects/objects/floors/protos/RectangleArena.proto"
EXTERNPROTO "../protos/P3Bot.proto"
EXTERNPROTO "https://raw.githubusercontent.com/cyberbotics/webots/R2023b/projects/objects/factory/containers/protos/CardboardBox.proto"

WorldInfo {
  info [
    "Simulation of the ROBOLAB P3Bot robot."
  ]
  title "ROBOLAB P3Bot"
  basicTimeStep 16
  contactProperties [
    ContactProperties {
      material1 "InteriorWheelMat"
      coulombFriction [
        0, 2, 0
      ]
      frictionRotation -0.785398 0
      bounce 0
      forceDependentSlip [
        10, 0
      ]
    }
    ContactProperties {
      material1 "ExteriorWheelMat"
      coulombFriction [
        0, 2, 0
      ]
      frictionRotation 0.785398 0
      bounce 0
      forceDependentSlip [
        10, 0
      ]
    }
  ]
}
Viewpoint {
  orientation 0.21383508780708002 0.2623587906213191 0.9409795004176535 4.839135189648948
  position -0.254707591454569 1.3622188817707472 -0.48535568959026665
}
TexturedBackground {
}
TexturedBackgroundLight {
}
RectangleArena {
  floorSize 3 3
}
CardboardBox {
  translation 0 0 0.08
  size 0.3 0.6 0.1
}
P3Bot {
  hidden linearVelocity_0 1.3757886212499938e-10 -1.4296495328166862e-08 -6.6050807103749256e-09
  hidden angularVelocity_0 3.488386514946201e-07 1.134252646935705e-08 -1.1167099460972814e-06
  hidden rotation_2 0.9999999999594926 9.000831501723444e-06 2.994392031250438e-11 3.1415999999999995
  hidden linearVelocity_2 9.619641753209686e-09 -2.0190283581060505e-06 8.695199069182389e-10
  hidden angularVelocity_2 0.0002012156282758704 2.1563224649437544e-07 9.298549450295453e-05
  hidden rotation_3 0.999999998543692 3.816168766269222e-05 -3.8161522545253334e-05 1.5708000014562842
  hidden linearVelocity_3 7.758123007135161e-09 -1.1829907162620083e-05 4.488202544806394e-09
  hidden angularVelocity_3 0.00012975056133182557 1.42904096251301e-07 0.00024513642089377574
  hidden rotation_4 -0.9999999999789226 4.591017196596975e-06 4.590997332250186e-06 1.5708000000210485
  hidden linearVelocity_4 4.196380456141533e-08 -5.334817162811613e-05 1.3559148997049705e-08
  hidden angularVelocity_4 0.00022225520813937838 2.2746380029076631e-07 0.0002884517709773294
  hidden rotation_5 0.9999999997851393 1.4658157923201228e-05 -1.46580945004953e-05 1.570800000214837
  hidden linearVelocity_5 6.578122148506818e-08 -7.586345495955622e-05 1.1378134097487637e-08
  hidden angularVelocity_5 0.00020063325330878885 2.0550746208031603e-07 0.0003344820256128405
  hidden rotation_6 -0.9999999997155475 -1.686575286674989e-05 -1.6865679892253918e-05 1.5708000002844151
  hidden linearVelocity_6 1.1273489688296186e-07 -0.00012414811037596578 1.2910578043732809e-08
  hidden angularVelocity_6 0.00018326532715979004 1.9027530517578975e-07 0.00032629256020388626
  hidden rotation_7 0.9999999999944347 2.3590812652274026e-06 -2.359071057988669e-06 1.5708000000055349
  hidden linearVelocity_7 1.2261694328424432e-07 -0.00013750841463252645 1.5120636630901893e-08
  hidden angularVelocity_7 0.0001802891535836914 1.8747425234791036e-07 0.00033262757332306394
  hidden rotation_8 -0.9999999999967044 -1.8154017396765172e-06 -1.8153938848224983e-06 1.5708000000032771
  hidden linearVelocity_8 5.1422888351972915e-08 -0.00016407642059408696 6.891681826538066e-08
  hidden angularVelocity_8 0.00018141480658072527 1.8845350976570613e-07 0.00033315444813784547
  hidden rotation_10 0.9999999989621174 -4.5560567331295045e-05 -1.5157066291217146e-10 3.1415999999999924
  hidden linearVelocity_10 8.461927500614617e-09 -3.239356639173134e-06 -1.4732507013590268e-08
  hidden angularVelocity_10 -0.0002058984842850728 -2.0554545277656132e-07 9.558295400616856e-05
  hidden rotation_11 0.999999998638354 3.690056571678047e-05 -3.690040605594521e-05 1.570800001361616
  hidden linearVelocity_11 -2.7170975903637162e-08 2.016383661259994e-05 -1.877011138703039e-08
  hidden angularVelocity_11 -0.00013221870601661895 -1.2319147529605084e-07 0.0002523539600202471
  hidden rotation_12 -0.9999999990209975 3.1289085457227806e-05 3.128895007606417e-05 1.5708000009789678
  hidden linearVelocity_12 -6.865064588457803e-08 5.688872155274997e-05 -1.9382463369679926e-08
  hidden angularVelocity_12 -3.765712353358166e-05 -1.7882242577179082e-08 0.0002077923646541733
  hidden rotation_13 0.999999999965289 5.891621897707497e-06 -5.8915964059227755e-06 1.5708000000346758
  hidden linearVelocity_13 -9.537425152554496e-08 8.503446378245446e-05 -2.2602602046152353e-08
  hidden angularVelocity_13 -6.006882657684704e-05 -4.678888389746903e-08 0.00016009994981500868
  hidden rotation_14 -1.1948728224322896e-05 0.7071062811245479 0.7071072811472385 3.1415661163304254
  hidden linearVelocity_14 -1.21165679789054e-07 0.00010865280763433787 -2.536468748583395e-08
  hidden angularVelocity_14 -7.745422042019026e-05 -6.648146773117586e-08 0.00016824591867891343
  hidden rotation_15 0.999999999999947 -2.305103860929694e-07 2.3050938872394677e-07 1.570800000000029
  hidden linearVelocity_15 -1.3053893943969837e-07 0.00011595048031548899 -2.683003479253497e-08
  hidden angularVelocity_15 -8.043865808278357e-05 -7.006639262288051e-08 0.00016189580606604397
  hidden rotation_16 -0.9999999999978896 -1.45276743813978e-06 -1.4527611523266218e-06 1.5708000000020974
  hidden linearVelocity_16 -1.0009368053770177e-07 0.0001290123182015676 -5.8024328680954265e-09
  hidden angularVelocity_16 -8.156751297040277e-05 -7.134884810587114e-08 0.0001624248555103197
  hidden linearVelocity_21 -1.3978589367796005e-07 2.59464558125486e-07 -4.7531559083307034e-08
  hidden angularVelocity_21 0.5848250525641718 0.0006049594553913855 -5.96623652831494e-05
  hidden linearVelocity_22 1.3923645119750975e-07 2.5975002065345246e-07 3.963385318359674e-08
  hidden angularVelocity_22 0.5848250525641717 0.0006049594553896209 -5.966236528074462e-05
  hidden linearVelocity_23 1.397900584618753e-07 -2.7595592907404094e-07 3.436409959192788e-08
  hidden angularVelocity_23 -0.5848243548879603 -0.0006049367698875807 5.742894753221821e-05
  hidden linearVelocity_24 -1.3923228641821716e-07 -2.7624139161085476e-07 -5.280131226729201e-08
  hidden angularVelocity_24 -0.5848243548879616 -0.000604936769887954 5.742894753647537e-05
  translation -0.0034821724659998047 -0.020394088415209507 0.08391744411836762
  rotation -3.199495826542243e-05 6.818374036174765e-05 -0.9999999971636503 1.5697619413738833
  wheels [
    DEF WHEEL1 HingeJoint {
      jointParameters HingeJointParameters {
        position 421.54353749657605
        axis 0 1 0
        anchor 0.125 -0.24 0.08
      }
      device [
        RotationalMotor {
          name "wheel1"
          maxVelocity 30
        }
        PositionSensor {
          name "wheel1sensor"
        }
      ]
      endPoint Solid {
        translation 0.125 -0.24 0.08
        rotation 0 -1 0 5.71306339163583
        children [
          Shape {
            appearance PBRAppearance {
              baseColor 0.75 0.75 0.75
              roughness 0.3
            }
            geometry Mesh {
              url [
                "../protos/p3bot_meshes/omnidirectional_wheel.stl"
              ]
            }
          }
        ]
        name "wheel1"
        contactMaterial "InteriorWheelMat"
        boundingObject Pose {
          rotation 1 0 0 1.5708
          children [
            Cylinder {
              height 0.04
              radius 0.08
              subdivision 24
            }
          ]
        }
        physics Physics {
          density -1
          mass 0.4
        }
      }
    }
    DEF WHEEL4 HingeJoint {
      jointParameters HingeJointParameters {
        position 1317.2434407736748
        axis 0 1 0
        anchor -0.125 -0.24 0.08
      }
      device [
        RotationalMotor {
          name "wheel4"
          maxVelocity 30
        }
        PositionSensor {
          name "wheel4sensor"
        }
      ]
      endPoint Solid {
        translation -0.125 -0.24 0.08
        rotation 0 -1 0 2.2254737340383404
        children [
          Shape {
            appearance PBRAppearance {
              baseColor 0.75 0.75 0.75
              roughness 0.3
            }
            geometry Mesh {
              url [
                "../protos/p3bot_meshes/omnidirectional_wheel.stl"
              ]
            }
          }
        ]
        name "wheel4"
        contactMaterial "InteriorWheelMat"
        boundingObject Pose {
          rotation 1 0 0 1.5708
          children [
            Cylinder {
              height 0.04
              radius 0.08
              subdivision 24
            }
          ]
        }
        physics Physics {
          density -1
          mass 0.4
        }
      }
    }
    DEF WHEEL2 HingeJoint {
      jointParameters HingeJointParameters {
        position -631.9075857936291
        axis 0 -1 0
        anchor -0.125 0.24 0.08
      }
      device [
        RotationalMotor {
          name "wheel2"
          maxVelocity 30
        }
        PositionSensor {
          name "wheel2sensor"
        }
      ]
      endPoint Solid {
        translation -0.125 0.24 0.08
        rotation 0.9750742472234182 -0.0020999945260396576 -0.22186888566149782 3.1406369860367747
        children [
          Shape {
            appearance PBRAppearance {
              baseColor 0.75 0.75 0.75
              roughness 0.3
            }
            geometry Mesh {
              url [
                "../protos/p3bot_meshes/omnidirectional_wheel.stl"
              ]
            }
          }
        ]
        name "wheel2"
        contactMaterial "ExteriorWheelMat"
        boundingObject Pose {
          rotation 1 0 0 1.5708
          children [
            Cylinder {
              height 0.04
              radius 0.08
              subdivision 24
            }
          ]
        }
        physics Physics {
          density -1
          mass 0.4
        }
      }
    }
    DEF WHEEL3 HingeJoint {
      jointParameters HingeJointParameters {
        position 171.8480823870383
        axis 0 -1 0
        anchor 0.125 0.24 0.08
      }
      device [
        RotationalMotor {
          name "wheel3"
          maxVelocity 30
        }
        PositionSensor {
          name "wheel3sensor"
        }
      ]
      endPoint Solid {
        translation 0.125 0.24 0.08
        rotation 0.8916767685356629 -0.001920383333119606 -0.4526685902309238 3.1396428507657714
        children [
          Shape {
            appearance PBRAppearance {
              baseColor 0.75 0.75 0.75
              roughness 0.3
            }
            geometry Mesh {
              url [
                "../protos/p3bot_meshes/omnidirectional_wheel.stl"
              ]
            }
          }
        ]
        name "wheel3"
        contactMaterial "ExteriorWheelMat"
        boundingObject Pose {
          rotation 1 0 0 1.5708
          children [
            Cylinder {
              height 0.04
              radius 0.08
              subdivision 24
            }
          ]
        }
        physics Physics {
          density -1
          mass 0.4
        }
      }
    }
  ]
}
